[2025-08-20T12:57:05.592+0000] {taskinstance.py:1979} INFO - Dependencies all met for dep_context=non-requeueable deps ti=<TaskInstance: customer_metrics.load_customer_transactions_raw scheduled__2025-08-19T00:00:00+00:00 [queued]>
[2025-08-20T12:57:05.706+0000] {taskinstance.py:1979} INFO - Dependencies all met for dep_context=requeueable deps ti=<TaskInstance: customer_metrics.load_customer_transactions_raw scheduled__2025-08-19T00:00:00+00:00 [queued]>
[2025-08-20T12:57:05.706+0000] {taskinstance.py:2193} INFO - Starting attempt 1 of 1
[2025-08-20T12:57:05.719+0000] {taskinstance.py:2214} INFO - Executing <Task(AirbyteTriggerSyncOperator): load_customer_transactions_raw> on 2025-08-19 00:00:00+00:00
[2025-08-20T12:57:05.727+0000] {standard_task_runner.py:60} INFO - Started process 295 to run task
[2025-08-20T12:57:05.730+0000] {standard_task_runner.py:87} INFO - Running: ['airflow', 'tasks', 'run', 'customer_metrics', 'load_customer_transactions_raw', 'scheduled__2025-08-19T00:00:00+00:00', '--job-id', '95', '--raw', '--subdir', 'DAGS_FOLDER/customer_metrics.py', '--cfg-path', '/tmp/tmpc4pzlj0z']
[2025-08-20T12:57:05.732+0000] {standard_task_runner.py:88} INFO - Job 95: Subtask load_customer_transactions_raw
[2025-08-20T12:57:05.785+0000] {task_command.py:423} INFO - Running <TaskInstance: customer_metrics.load_customer_transactions_raw scheduled__2025-08-19T00:00:00+00:00 [running]> on host f3fd0a28023e
[2025-08-20T12:57:05.863+0000] {taskinstance.py:2510} INFO - Exporting env vars: AIRFLOW_CTX_DAG_OWNER='airflow' AIRFLOW_CTX_DAG_ID='customer_metrics' AIRFLOW_CTX_TASK_ID='load_customer_transactions_raw' AIRFLOW_CTX_EXECUTION_DATE='2025-08-19T00:00:00+00:00' AIRFLOW_CTX_TRY_NUMBER='1' AIRFLOW_CTX_DAG_RUN_ID='scheduled__2025-08-19T00:00:00+00:00'
[2025-08-20T12:57:05.883+0000] {taskinstance.py:2728} ERROR - Task failed with exception
Traceback (most recent call last):
  File "/home/airflow/.local/lib/python3.8/site-packages/airflow/models/taskinstance.py", line 444, in _execute_task
    result = _execute_callable(context=context, **execute_callable_kwargs)
  File "/home/airflow/.local/lib/python3.8/site-packages/airflow/models/taskinstance.py", line 414, in _execute_callable
    return execute_callable(context=context, **execute_callable_kwargs)
  File "/home/airflow/.local/lib/python3.8/site-packages/airflow/providers/airbyte/operators/airbyte.py", line 81, in execute
    job_object = hook.submit_sync_connection(connection_id=self.connection_id)
  File "/home/airflow/.local/lib/python3.8/site-packages/airflow/providers/airbyte/hooks/airbyte.py", line 149, in submit_sync_connection
    return self.run(
  File "/home/airflow/.local/lib/python3.8/site-packages/airflow/providers/http/hooks/http.py", line 159, in run
    session = self.get_conn(headers)
  File "/home/airflow/.local/lib/python3.8/site-packages/airflow/providers/http/hooks/http.py", line 101, in get_conn
    conn = self.get_connection(self.http_conn_id)
  File "/home/airflow/.local/lib/python3.8/site-packages/airflow/hooks/base.py", line 82, in get_connection
    conn = Connection.get_connection_from_secrets(conn_id)
  File "/home/airflow/.local/lib/python3.8/site-packages/airflow/models/connection.py", line 514, in get_connection_from_secrets
    raise AirflowNotFoundException(f"The conn_id `{conn_id}` isn't defined")
airflow.exceptions.AirflowNotFoundException: The conn_id `airbyte` isn't defined
[2025-08-20T12:57:05.886+0000] {taskinstance.py:1149} INFO - Marking task as FAILED. dag_id=customer_metrics, task_id=load_customer_transactions_raw, execution_date=20250819T000000, start_date=20250820T125705, end_date=20250820T125705
[2025-08-20T12:57:05.899+0000] {standard_task_runner.py:107} ERROR - Failed to execute job 95 for task load_customer_transactions_raw (The conn_id `airbyte` isn't defined; 295)
[2025-08-20T12:57:05.942+0000] {local_task_job_runner.py:234} INFO - Task exited with return code 1
[2025-08-20T12:57:05.975+0000] {taskinstance.py:3309} INFO - 0 downstream tasks scheduled from follow-on schedule check
