[2025-08-20T21:16:42.144+0000] {taskinstance.py:1979} INFO - Dependencies all met for dep_context=non-requeueable deps ti=<TaskInstance: fraud_detection_pipeline.audit_customer_transactions manual__2025-08-20T21:14:06.011596+00:00 [queued]>
[2025-08-20T21:16:42.350+0000] {taskinstance.py:1979} INFO - Dependencies all met for dep_context=requeueable deps ti=<TaskInstance: fraud_detection_pipeline.audit_customer_transactions manual__2025-08-20T21:14:06.011596+00:00 [queued]>
[2025-08-20T21:16:42.351+0000] {taskinstance.py:2193} INFO - Starting attempt 1 of 1
[2025-08-20T21:16:42.368+0000] {taskinstance.py:2214} INFO - Executing <Task(_PythonExternalDecoratedOperator): audit_customer_transactions> on 2025-08-20 21:14:06.011596+00:00
[2025-08-20T21:16:42.377+0000] {standard_task_runner.py:60} INFO - Started process 1510 to run task
[2025-08-20T21:16:42.381+0000] {standard_task_runner.py:87} INFO - Running: ['airflow', 'tasks', 'run', 'fraud_detection_pipeline', 'audit_customer_transactions', 'manual__2025-08-20T21:14:06.011596+00:00', '--job-id', '112', '--raw', '--subdir', 'DAGS_FOLDER/fraud_detection_pipeline.py', '--cfg-path', '/tmp/tmp9w6c5z70']
[2025-08-20T21:16:42.384+0000] {standard_task_runner.py:88} INFO - Job 112: Subtask audit_customer_transactions
[2025-08-20T21:16:42.456+0000] {task_command.py:423} INFO - Running <TaskInstance: fraud_detection_pipeline.audit_customer_transactions manual__2025-08-20T21:14:06.011596+00:00 [running]> on host f3fd0a28023e
[2025-08-20T21:16:42.580+0000] {taskinstance.py:2510} INFO - Exporting env vars: AIRFLOW_CTX_DAG_OWNER='airflow' AIRFLOW_CTX_DAG_ID='fraud_detection_pipeline' AIRFLOW_CTX_TASK_ID='audit_customer_transactions' AIRFLOW_CTX_EXECUTION_DATE='2025-08-20T21:14:06.011596+00:00' AIRFLOW_CTX_TRY_NUMBER='1' AIRFLOW_CTX_DAG_RUN_ID='manual__2025-08-20T21:14:06.011596+00:00'
[2025-08-20T21:16:42.601+0000] {python.py:913} WARNING - When checking for Airflow installed in virtual environment got [Errno 2] No such file or directory: '/opt/airflow/soda_env/bin/python'
[2025-08-20T21:16:42.603+0000] {python.py:914} WARNING - This means that Airflow is not properly installed by  /opt/airflow/soda_env/bin/python. Airflow context keys will not be available. Please Install Airflow 2.8.2 in your environment to access them.
[2025-08-20T21:16:42.620+0000] {taskinstance.py:2728} ERROR - Task failed with exception
Traceback (most recent call last):
  File "/home/airflow/.local/lib/python3.8/site-packages/airflow/models/taskinstance.py", line 444, in _execute_task
    result = _execute_callable(context=context, **execute_callable_kwargs)
  File "/home/airflow/.local/lib/python3.8/site-packages/airflow/models/taskinstance.py", line 414, in _execute_callable
    return execute_callable(context=context, **execute_callable_kwargs)
  File "/home/airflow/.local/lib/python3.8/site-packages/airflow/decorators/base.py", line 241, in execute
    return_value = super().execute(context)
  File "/home/airflow/.local/lib/python3.8/site-packages/airflow/operators/python.py", line 401, in execute
    return super().execute(context=serializable_context)
  File "/home/airflow/.local/lib/python3.8/site-packages/airflow/operators/python.py", line 200, in execute
    return_value = self.execute_callable()
  File "/home/airflow/.local/lib/python3.8/site-packages/airflow/operators/python.py", line 844, in execute_callable
    raise ValueError(f"Python Path '{python_path}' must exists")
ValueError: Python Path '/opt/airflow/soda_env/bin/python' must exists
[2025-08-20T21:16:42.640+0000] {taskinstance.py:1149} INFO - Marking task as FAILED. dag_id=fraud_detection_pipeline, task_id=audit_customer_transactions, execution_date=20250820T211406, start_date=20250820T211642, end_date=20250820T211642
[2025-08-20T21:16:42.672+0000] {standard_task_runner.py:107} ERROR - Failed to execute job 112 for task audit_customer_transactions (Python Path '/opt/airflow/soda_env/bin/python' must exists; 1510)
[2025-08-20T21:16:42.713+0000] {local_task_job_runner.py:234} INFO - Task exited with return code 1
[2025-08-20T21:16:42.778+0000] {taskinstance.py:3309} INFO - 0 downstream tasks scheduled from follow-on schedule check
