[2025-08-20T21:05:12.182+0000] {taskinstance.py:1979} INFO - Dependencies all met for dep_context=non-requeueable deps ti=<TaskInstance: fraud_detection_pipeline.load_customer_transactions_raw manual__2025-08-20T21:04:57.350531+00:00 [queued]>
[2025-08-20T21:05:12.319+0000] {taskinstance.py:1979} INFO - Dependencies all met for dep_context=requeueable deps ti=<TaskInstance: fraud_detection_pipeline.load_customer_transactions_raw manual__2025-08-20T21:04:57.350531+00:00 [queued]>
[2025-08-20T21:05:12.319+0000] {taskinstance.py:2193} INFO - Starting attempt 1 of 1
[2025-08-20T21:05:12.335+0000] {taskinstance.py:2214} INFO - Executing <Task(AirbyteTriggerSyncOperator): load_customer_transactions_raw> on 2025-08-20 21:04:57.350531+00:00
[2025-08-20T21:05:12.343+0000] {standard_task_runner.py:60} INFO - Started process 554 to run task
[2025-08-20T21:05:12.346+0000] {standard_task_runner.py:87} INFO - Running: ['airflow', 'tasks', 'run', 'fraud_detection_pipeline', 'load_customer_transactions_raw', 'manual__2025-08-20T21:04:57.350531+00:00', '--job-id', '106', '--raw', '--subdir', 'DAGS_FOLDER/fraud_detection_pipeline.py', '--cfg-path', '/tmp/tmpuxv95bjy']
[2025-08-20T21:05:12.349+0000] {standard_task_runner.py:88} INFO - Job 106: Subtask load_customer_transactions_raw
[2025-08-20T21:05:12.413+0000] {task_command.py:423} INFO - Running <TaskInstance: fraud_detection_pipeline.load_customer_transactions_raw manual__2025-08-20T21:04:57.350531+00:00 [running]> on host f3fd0a28023e
[2025-08-20T21:05:12.533+0000] {taskinstance.py:2510} INFO - Exporting env vars: AIRFLOW_CTX_DAG_OWNER='airflow' AIRFLOW_CTX_DAG_ID='fraud_detection_pipeline' AIRFLOW_CTX_TASK_ID='load_customer_transactions_raw' AIRFLOW_CTX_EXECUTION_DATE='2025-08-20T21:04:57.350531+00:00' AIRFLOW_CTX_TRY_NUMBER='1' AIRFLOW_CTX_DAG_RUN_ID='manual__2025-08-20T21:04:57.350531+00:00'
[2025-08-20T21:05:12.551+0000] {base.py:83} INFO - Using connection ID 'airbyte' for task execution.
[2025-08-20T21:05:15.183+0000] {airbyte.py:86} INFO - Job 47 was submitted to Airbyte Server
[2025-08-20T21:05:15.184+0000] {airbyte.py:88} INFO - Waiting for job 47 to complete
[2025-08-20T21:05:18.204+0000] {base.py:83} INFO - Using connection ID 'airbyte' for task execution.
[2025-08-20T21:05:21.247+0000] {base.py:83} INFO - Using connection ID 'airbyte' for task execution.
[2025-08-20T21:05:24.310+0000] {base.py:83} INFO - Using connection ID 'airbyte' for task execution.
[2025-08-20T21:05:27.377+0000] {base.py:83} INFO - Using connection ID 'airbyte' for task execution.
[2025-08-20T21:05:30.413+0000] {base.py:83} INFO - Using connection ID 'airbyte' for task execution.
[2025-08-20T21:05:33.449+0000] {base.py:83} INFO - Using connection ID 'airbyte' for task execution.
[2025-08-20T21:05:36.485+0000] {base.py:83} INFO - Using connection ID 'airbyte' for task execution.
[2025-08-20T21:05:39.536+0000] {base.py:83} INFO - Using connection ID 'airbyte' for task execution.
[2025-08-20T21:05:42.577+0000] {base.py:83} INFO - Using connection ID 'airbyte' for task execution.
[2025-08-20T21:05:45.621+0000] {base.py:83} INFO - Using connection ID 'airbyte' for task execution.
[2025-08-20T21:05:48.661+0000] {base.py:83} INFO - Using connection ID 'airbyte' for task execution.
[2025-08-20T21:05:51.704+0000] {base.py:83} INFO - Using connection ID 'airbyte' for task execution.
[2025-08-20T21:05:54.746+0000] {base.py:83} INFO - Using connection ID 'airbyte' for task execution.
[2025-08-20T21:05:57.775+0000] {base.py:83} INFO - Using connection ID 'airbyte' for task execution.
[2025-08-20T21:06:00.811+0000] {base.py:83} INFO - Using connection ID 'airbyte' for task execution.
[2025-08-20T21:06:00.838+0000] {taskinstance.py:2728} ERROR - Task failed with exception
Traceback (most recent call last):
  File "/home/airflow/.local/lib/python3.8/site-packages/airflow/models/taskinstance.py", line 444, in _execute_task
    result = _execute_callable(context=context, **execute_callable_kwargs)
  File "/home/airflow/.local/lib/python3.8/site-packages/airflow/models/taskinstance.py", line 414, in _execute_callable
    return execute_callable(context=context, **execute_callable_kwargs)
  File "/home/airflow/.local/lib/python3.8/site-packages/airflow/providers/airbyte/operators/airbyte.py", line 111, in execute
    hook.wait_for_job(job_id=self.job_id, wait_seconds=self.wait_seconds, timeout=self.timeout)
  File "/home/airflow/.local/lib/python3.8/site-packages/airflow/providers/airbyte/hooks/airbyte.py", line 141, in wait_for_job
    raise Exception(f"Encountered unexpected state `{state}` for job_id `{job_id}`")
Exception: Encountered unexpected state `failed` for job_id `47`
[2025-08-20T21:06:00.861+0000] {taskinstance.py:1149} INFO - Marking task as FAILED. dag_id=fraud_detection_pipeline, task_id=load_customer_transactions_raw, execution_date=20250820T210457, start_date=20250820T210512, end_date=20250820T210600
[2025-08-20T21:06:00.897+0000] {standard_task_runner.py:107} ERROR - Failed to execute job 106 for task load_customer_transactions_raw (Encountered unexpected state `failed` for job_id `47`; 554)
[2025-08-20T21:06:00.941+0000] {local_task_job_runner.py:234} INFO - Task exited with return code 1
[2025-08-20T21:06:01.014+0000] {taskinstance.py:3309} INFO - 0 downstream tasks scheduled from follow-on schedule check
